<?xml version="1.0"?>
<robot name="hexapod_master">

  <!-- Materials -->
  <material name="dark_gray"><color rgba="0.2 0.2 0.2 1.0"/></material>
  <material name="green"><color rgba="0.41 0.61 0.5 1.0"/></material>
  <material name="black"><color rgba="0.0 0.0 0.0 1.0"/></material>

  <!-- Central Body -->
  <link name="base_link">
    <visual>
      <geometry><box size="0.24 0.16 0.03"/></geometry>
      <material name="dark_gray"/>
    </visual>
  </link>

  <!-- Macro for a single leg -->
  <!-- Since plain URDF doesn't support macros well, I will repeat the structure for 6 legs -->
  <!-- Leg RF (Right Front) -->
  <joint name="rf_coxa_joint" type="revolute">
    <parent link="base_link"/><child link="rf_coxa_link"/>
    <origin xyz="0.12 -0.08 0" rpy="0 0 -0.785"/>
    <axis xyz="0 0 1"/><limit lower="-1.57" upper="1.57" effort="10" velocity="1.0"/>
  </joint>
  <link name="rf_coxa_link">
    <visual><origin xyz="0.015 0 0"/><geometry><box size="0.03 0.02 0.02"/></geometry><material name="green"/></visual>
  </link>
  <joint name="rf_femur_joint" type="revolute">
    <parent link="rf_coxa_link"/><child link="rf_femur_link"/>
    <origin xyz="0.03 0 0" rpy="0 0 0"/><axis xyz="0 1 0"/>
    <limit lower="-1.57" upper="1.57" effort="10" velocity="1.0"/>
  </joint>
  <link name="rf_femur_link">
    <visual><origin xyz="0.025 0 0"/><geometry><box size="0.05 0.015 0.015"/></geometry><material name="dark_gray"/></visual>
  </link>
  <joint name="rf_tibia_joint" type="revolute">
    <parent link="rf_femur_link"/><child link="rf_tibia_link"/>
    <origin xyz="0.05 0 0" rpy="0 0 0"/><axis xyz="0 1 0"/>
    <limit lower="-3.14" upper="0" effort="10" velocity="1.0"/>
  </joint>
  <link name="rf_tibia_link">
    <visual><origin xyz="0.04 0 0"/><geometry><box size="0.08 0.01 0.01"/></geometry><material name="green"/></visual>
  </link>

  <!-- Leg RM (Right Middle) -->
  <joint name="rm_coxa_joint" type="revolute">
    <parent link="base_link"/><child link="rm_coxa_link"/>
    <origin xyz="0.0 -0.10 0" rpy="0 0 -1.571"/>
    <axis xyz="0 0 1"/><limit lower="-1.57" upper="1.57" effort="10" velocity="1.0"/>
  </joint>
  <link name="rm_coxa_link">
    <visual><origin xyz="0.015 0 0"/><geometry><box size="0.03 0.02 0.02"/></geometry><material name="green"/></visual>
  </link>
  <joint name="rm_femur_joint" type="revolute">
    <parent link="rm_coxa_link"/><child link="rm_femur_link"/>
    <origin xyz="0.03 0 0" rpy="0 0 0"/><axis xyz="0 1 0"/>
    <limit lower="-1.57" upper="1.57" effort="10" velocity="1.0"/>
  </joint>
  <link name="rm_femur_link">
    <visual><origin xyz="0.025 0 0"/><geometry><box size="0.05 0.015 0.015"/></geometry><material name="dark_gray"/></visual>
  </link>
  <joint name="rm_tibia_joint" type="revolute">
    <parent link="rm_femur_link"/><child link="rm_tibia_link"/>
    <origin xyz="0.05 0 0" rpy="0 0 0"/><axis xyz="0 1 0"/>
    <limit lower="-3.14" upper="0" effort="10" velocity="1.0"/>
  </joint>
  <link name="rm_tibia_link">
    <visual><origin xyz="0.04 0 0"/><geometry><box size="0.08 0.01 0.01"/></geometry><material name="green"/></visual>
  </link>

  <!-- Leg RB (Right Back) -->
  <joint name="rb_coxa_joint" type="revolute">
    <parent link="base_link"/><child link="rb_coxa_link"/>
    <origin xyz="-0.12 -0.08 0" rpy="0 0 -2.356"/>
    <axis xyz="0 0 1"/><limit lower="-1.57" upper="1.57" effort="10" velocity="1.0"/>
  </joint>
  <link name="rb_coxa_link">
    <visual><origin xyz="0.015 0 0"/><geometry><box size="0.03 0.02 0.02"/></geometry><material name="green"/></visual>
  </link>
  <joint name="rb_femur_joint" type="revolute">
    <parent link="rb_coxa_link"/><child link="rb_femur_link"/>
    <origin xyz="0.03 0 0" rpy="0 0 0"/><axis xyz="0 1 0"/>
    <limit lower="-1.57" upper="1.57" effort="10" velocity="1.0"/>
  </joint>
  <link name="rb_femur_link">
    <visual><origin xyz="0.025 0 0"/><geometry><box size="0.05 0.015 0.015"/></geometry><material name="dark_gray"/></visual>
  </link>
  <joint name="rb_tibia_joint" type="revolute">
    <parent link="rb_femur_link"/><child link="rb_tibia_link"/>
    <origin xyz="0.05 0 0" rpy="0 0 0"/><axis xyz="0 1 0"/>
    <limit lower="-3.14" upper="0" effort="10" velocity="1.0"/>
  </joint>
  <link name="rb_tibia_link">
    <visual><origin xyz="0.04 0 0"/><geometry><box size="0.08 0.01 0.01"/></geometry><material name="green"/></visual>
  </link>

  <!-- Leg LF (Left Front) -->
  <joint name="lf_coxa_joint" type="revolute">
    <parent link="base_link"/><child link="lf_coxa_link"/>
    <origin xyz="0.12 0.08 0" rpy="0 0 0.785"/>
    <axis xyz="0 0 1"/><limit lower="-1.57" upper="1.57" effort="10" velocity="1.0"/>
  </joint>
  <link name="lf_coxa_link">
    <visual><origin xyz="0.015 0 0"/><geometry><box size="0.03 0.02 0.02"/></geometry><material name="green"/></visual>
  </link>
  <joint name="lf_femur_joint" type="revolute">
    <parent link="lf_coxa_link"/><child link="lf_femur_link"/>
    <origin xyz="0.03 0 0" rpy="0 0 0"/><axis xyz="0 1 0"/>
    <limit lower="-1.57" upper="1.57" effort="10" velocity="1.0"/>
  </joint>
  <link name="lf_femur_link">
    <visual><origin xyz="0.025 0 0"/><geometry><box size="0.05 0.015 0.015"/></geometry><material name="dark_gray"/></visual>
  </link>
  <joint name="lf_tibia_joint" type="revolute">
    <parent link="lf_femur_link"/><child link="lf_tibia_link"/>
    <origin xyz="0.05 0 0" rpy="0 0 0"/><axis xyz="0 1 0"/>
    <limit lower="-3.14" upper="0" effort="10" velocity="1.0"/>
  </joint>
  <link name="lf_tibia_link">
    <visual><origin xyz="0.04 0 0"/><geometry><box size="0.08 0.01 0.01"/></geometry><material name="green"/></visual>
  </link>

  <!-- Leg LM (Left Middle) -->
  <joint name="lm_coxa_joint" type="revolute">
    <parent link="base_link"/><child link="lm_coxa_link"/>
    <origin xyz="0.0 0.10 0" rpy="0 0 1.571"/>
    <axis xyz="0 0 1"/><limit lower="-1.57" upper="1.57" effort="10" velocity="1.0"/>
  </joint>
  <link name="lm_coxa_link">
    <visual><origin xyz="0.015 0 0"/><geometry><box size="0.03 0.02 0.02"/></geometry><material name="green"/></visual>
  </link>
  <joint name="lm_femur_joint" type="revolute">
    <parent link="lm_coxa_link"/><child link="lm_femur_link"/>
    <origin xyz="0.03 0 0" rpy="0 0 0"/><axis xyz="0 1 0"/>
    <limit lower="-1.57" upper="1.57" effort="10" velocity="1.0"/>
  </joint>
  <link name="lm_femur_link">
    <visual><origin xyz="0.025 0 0"/><geometry><box size="0.05 0.015 0.015"/></geometry><material name="dark_gray"/></visual>
  </link>
  <joint name="lm_tibia_joint" type="revolute">
    <parent link="lm_femur_link"/><child link="lm_tibia_link"/>
    <origin xyz="0.05 0 0" rpy="0 0 0"/><axis xyz="0 1 0"/>
    <limit lower="-3.14" upper="0" effort="10" velocity="1.0"/>
  </joint>
  <link name="lm_tibia_link">
    <visual><origin xyz="0.04 0 0"/><geometry><box size="0.08 0.01 0.01"/></geometry><material name="green"/></visual>
  </link>

  <!-- Leg LB (Left Back) -->
  <joint name="lb_coxa_joint" type="revolute">
    <parent link="base_link"/><child link="lb_coxa_link"/>
    <origin xyz="-0.12 0.08 0" rpy="0 0 2.356"/>
    <axis xyz="0 0 1"/><limit lower="-1.57" upper="1.57" effort="10" velocity="1.0"/>
  </joint>
  <link name="lb_coxa_link">
    <visual><origin xyz="0.015 0 0"/><geometry><box size="0.03 0.02 0.02"/></geometry><material name="green"/></visual>
  </link>
  <joint name="lb_femur_joint" type="revolute">
    <parent link="lb_coxa_link"/><child link="lb_femur_link"/>
    <origin xyz="0.03 0 0" rpy="0 0 0"/><axis xyz="0 1 0"/>
    <limit lower="-1.57" upper="1.57" effort="10" velocity="1.0"/>
  </joint>
  <link name="lb_femur_link">
    <visual><origin xyz="0.025 0 0"/><geometry><box size="0.05 0.015 0.015"/></geometry><material name="dark_gray"/></visual>
  </link>
  <joint name="lb_tibia_joint" type="revolute">
    <parent link="lb_femur_link"/><child link="lb_tibia_link"/>
    <origin xyz="0.05 0 0" rpy="0 0 0"/><axis xyz="0 1 0"/>
    <limit lower="-3.14" upper="0" effort="10" velocity="1.0"/>
  </joint>
  <link name="lb_tibia_link">
    <visual><origin xyz="0.04 0 0"/><geometry><box size="0.08 0.01 0.01"/></geometry><material name="green"/></visual>
  </link>

</robot>
